# app/modules/delivery/tasks.py  
# Celery tasks specific to the Delivery module

from app.worker.celery_app import celery_app  
from app.core.logging_setup import logger  
import asyncio

# Import services needed by tasks  
# from app.modules.delivery.service import DeliveryService  
# from app.core.config import settings \# For PromptOS queue name

# Placeholder: Function to get DeliveryService instance within task context  
def _get_delivery_service_in_task():  
    logger.warning("Attempting to get DeliveryService in task \- DI needs proper setup\!")  
    return None

# Placeholder: Function to get PromptOS task sender  
def _get_promptos_task_sender():  
     \# Use celery_app instance if defined in this worker context  
     \# Or create a new Celery client configured for the main broker  
     \# from celery import Celery  
     \# client \= Celery(broker=settings.CELERY_BROKER_URL)  
     \# return client  
     return celery_app \# Assume worker uses the same app instance

@celery_app.task(bind=True, name="delivery.assign_courier")  
def assign_courier_task(self, delivery_id: str):  
    task_id \= self.request.id  
    log \= logger.bind(celery_task_id=task_id, task_name="assign_courier", delivery_id=delivery_id)  
    log.info("Starting courier assignment task.")  
    try:  
        async def run_assignment():  
            \# delivery_service \= _get_delivery_service_in_task() \# Needs impl  
            \# await delivery_service.assign_best_courier(delivery_id) \# Needs impl  
            log.warning("Courier assignment logic not implemented.")  
            await asyncio.sleep(2) \# Simulate work  
            return {"assigned": True} \# Simulate success

        result \= asyncio.run(run_assignment())  
        log.success("Courier assignment processed (simulation).")  
        return {"delivery_id": delivery_id, "status": "success", "result": result}  
    except Exception as e:  
        log.exception("Error during courier assignment task.")  
        raise self.retry(exc=e, countdown=60, max_retries=3)

@celery_app.task(bind=True, name="delivery.trigger_fallback")  
def trigger_fallback_task(self, delivery_id: str, reason: str):  
    task_id \= self.request.id  
    log \= logger.bind(celery_task_id=task_id, task_name="trigger_fallback", delivery_id=delivery_id)  
    log.warning(f"Triggering PromptOS fallback for delivery. Reason: {reason}")  
    try:  
        \# 1\. Gather context (simplified for now)  
        \# delivery_service \= _get_delivery_service_in_task()  
        \# context_summary \= asyncio.run(delivery_service.get_fallback_context(delivery_id))  
        context_summary \= {"current_status": "delayed", "last_location": "unknown"} \# Placeholder

        \# 2\. Prepare payload for PromptOS task  
        payload \= {  
            "source_service": "agentos_delivery",  
            "entity_type": "delivery",  
            "entity_id": delivery_id,  
            "reason": reason,  
            "context_summary": context_summary  
        }

        \# 3\. Send task to PromptOS queue  
        promptos_sender \= _get_promptos_task_sender()  
        if promptos_sender:  
            promptos_sender.send_task(  
                'promptos.handle_fallback', \# Target task name  
                args=\[payload\],  
                queue=settings.PROMPTOS_TASK_QUEUE \# Target queue  
            )  
            log.info("Fallback task dispatched to PromptOS queue.")  
            return {"delivery_id": delivery_id, "status": "fallback_triggered"}  
        else:  
            raise RuntimeError("Celery client for PromptOS dispatch not available.")

    except Exception as e:  
        log.exception("Error triggering fallback task.")  
        \# Maybe retry dispatching?  
        raise self.retry(exc=e, countdown=45, max_retries=2)

# Add monitor_delivery_task if needed (often better handled by external scheduler/cron)
